Traceback (most recent call last):
  File "/home/runner/.virtualenvs/.venv/lib/python3.10/site-packages/jupyter_cache/executors/utils.py", line 51, in single_nb_execution
    executenb(
  File "/home/runner/.virtualenvs/.venv/lib/python3.10/site-packages/nbclient/client.py", line 1204, in execute
    return NotebookClient(nb=nb, resources=resources, km=km, **kwargs).execute()
  File "/home/runner/.virtualenvs/.venv/lib/python3.10/site-packages/nbclient/util.py", line 84, in wrapped
    return just_run(coro(*args, **kwargs))
  File "/home/runner/.virtualenvs/.venv/lib/python3.10/site-packages/nbclient/util.py", line 62, in just_run
    return loop.run_until_complete(coro)
  File "/opt/hostedtoolcache/Python/3.10.9/x64/lib/python3.10/asyncio/base_events.py", line 649, in run_until_complete
    return future.result()
  File "/home/runner/.virtualenvs/.venv/lib/python3.10/site-packages/nbclient/client.py", line 663, in async_execute
    await self.async_execute_cell(
  File "/home/runner/.virtualenvs/.venv/lib/python3.10/site-packages/nbclient/client.py", line 965, in async_execute_cell
    await self._check_raise_for_error(cell, cell_index, exec_reply)
  File "/home/runner/.virtualenvs/.venv/lib/python3.10/site-packages/nbclient/client.py", line 862, in _check_raise_for_error
    raise CellExecutionError.from_cell_and_msg(cell, exec_reply_content)
nbclient.exceptions.CellExecutionError: An error occurred while executing the following cell:
------------------
from functions import find_scenarios_with_segment_i
from functions import assemble_analysis_cases
from functions import exceedance_prob
from functions import plot_curves
from functions import sensitivity_analysis
from functions import compute_benefit
from functions import set_TUDstyle
------------------

[0;31m---------------------------------------------------------------------------[0m
[0;31mModuleNotFoundError[0m                       Traceback (most recent call last)
Cell [0;32mIn[2], line 1[0m
[0;32m----> 1[0m [38;5;28;01mfrom[39;00m [38;5;21;01mfunctions[39;00m [38;5;28;01mimport[39;00m find_scenarios_with_segment_i
[1;32m      2[0m [38;5;28;01mfrom[39;00m [38;5;21;01mfunctions[39;00m [38;5;28;01mimport[39;00m assemble_analysis_cases
[1;32m      3[0m [38;5;28;01mfrom[39;00m [38;5;21;01mfunctions[39;00m [38;5;28;01mimport[39;00m exceedance_prob

[0;31mModuleNotFoundError[0m: No module named 'functions'
ModuleNotFoundError: No module named 'functions'

